{"summary": {"file_name": "udistrict.json"}, "goals": [{"index": 0, "question": "What is the distribution of housing prices in the University District?", "visualization": "Histogram of the 'price' field", "rationale": "This visualization will help us understand the range of housing prices in the University District and identify any outliers."}, {"index": 1, "question": "What is the relationship between the number of bedrooms and the price of a property in the University District?", "visualization": "Scatter plot of the 'bedrooms' field against the 'price' field", "rationale": "This visualization will help us understand if there is a correlation between the number of bedrooms and the price of a property in the University District."}, {"index": 2, "question": "What is the most common type of property in the University District?", "visualization": "Bar chart of the 'property_type' field", "rationale": "This visualization will help us understand the distribution of property types in the University District and identify any trends."}, {"index": 3, "question": "What is the average rating of properties in the University District?", "visualization": "Box plot of the 'review_scores_rating' field", "rationale": "This visualization will help us understand the distribution of review scores for properties in the University District and identify any outliers."}, {"index": 4, "question": "What is the distribution of the distance between properties and the University of Washington?", "visualization": "Histogram of the 'distance' field", "rationale": "This visualization will help us understand the proximity of properties to the University of Washington and identify any trends or patterns."}], "code": [["import matplotlib.pyplot as plt\nimport pandas as pd\ndef plot(data: pd.DataFrame):\n    data['price'] = pd.to_numeric(data['price'], errors='coerce')\n    data = data.dropna(subset=['price'])\n    plt.hist(data['price'], bins=20, color='green', alpha=0.5)\n    plt.axvline(data['price'].median(), color='red', linestyle='dashed', linewidth=1, label='Median: {:.2f}'.format(data['price'].median()))\n    plt.xlabel('Price')\n    plt.ylabel('Frequency')\n    plt.legend(loc='upper right')\n    return plt;\n\nchart = plot(data)"], ["import matplotlib.pyplot as plt\nimport pandas as pd\n\ndef plot(data: pd.DataFrame):\n    data['date'] = pd.to_datetime(data['date'], format='%Y-%m-%d', errors='coerce')\n    plt.scatter(data['bedrooms'], data['price'], alpha=0.5)\n    plt.xlabel('Number of Bedrooms')\n    plt.ylabel('Price')\n    plt.title('What is the relationship between the number of bedrooms and the price of a property in the University District?')\n    return plt\n\nchart = plot(data)"], ["import matplotlib.pyplot as plt\nimport pandas as pd\ndef plot(data: pd.DataFrame):\n    data['property_type'].value_counts().plot(kind='bar')\n    plt.title('What is the most common type of property in the University District?', wrap=True)\n    return plt;\n\nchart = plot(data)"], ["import matplotlib.pyplot as plt\nimport pandas as pd\ndef plot(data: pd.DataFrame):\n    data['review_scores_rating'] = pd.to_numeric(data['review_scores_rating'], errors='coerce')\n    fig, ax = plt.subplots(figsize=(8,6))\n    ax.boxplot(data['review_scores_rating'].dropna(), vert=False, showmeans=True, meanline=True, labels=['Review Scores'])\n    ax.set_title('What is the average rating of properties in the University District?')\n    ax.axvline(data['review_scores_rating'].mean(), color='r', linestyle='--', label=f'Mean: {data[\"review_scores_rating\"].mean():.2f}')\n    ax.legend()\n    return plt;\n\nchart = plot(data)"], ["import matplotlib.pyplot as plt\nimport pandas as pd\ndef plot(data: pd.DataFrame):\n    data['distance'] = pd.to_numeric(data['distance'], errors='coerce')\n    data = data.dropna(subset=['distance'])\n    fig, ax = plt.subplots(figsize=(10, 6))\n    ax.hist(data['distance'], bins=20, color='blue', alpha=0.5)\n    ax.axvline(data['distance'].median(), color='red', linestyle='dashed', linewidth=2, label=f'Median: {data[\"distance\"].median():.2f}')\n    ax.set_xlabel('Distance from University of Washington')\n    ax.set_ylabel('Frequency')\n    ax.legend()\n    plt.title('What is the distribution of the distance between properties and the University of Washington?', wrap=True)\n    return plt;\n\nchart = plot(data)"]], "filename": "udistrict.json", "chart": [[{"spec": null, "status": false, "raster": null, "code": "import matplotlib.pyplot as plt\nimport pandas as pd\ndef plot(data: pd.DataFrame):\n    data['price'] = pd.to_numeric(data['price'], errors='coerce')\n    data = data.dropna(subset=['price'])\n    plt.hist(data['price'], bins=20, color='green', alpha=0.5)\n    plt.axvline(data['price'].median(), color='red', linestyle='dashed', linewidth=1, label='Median: {:.2f}'.format(data['price'].median()))\n    plt.xlabel('Price')\n    plt.ylabel('Frequency')\n    plt.legend(loc='upper right')\n    return plt;\n\nchart = plot(data)", "library": "matplotlib", "error": {"message": "'price'", "traceback": "Traceback (most recent call last):\n  File \"/home/victordibia/.local/lib/python3.9/site-packages/pandas/core/indexes/base.py\", line 3621, in get_loc\n    return self._engine.get_loc(casted_key)\n  File \"pandas/_libs/index.pyx\", line 136, in pandas._libs.index.IndexEngine.get_loc\n  File \"pandas/_libs/index.pyx\", line 163, in pandas._libs.index.IndexEngine.get_loc\n  File \"pandas/_libs/hashtable_class_helper.pxi\", line 5198, in pandas._libs.hashtable.PyObjectHashTable.get_item\n  File \"pandas/_libs/hashtable_class_helper.pxi\", line 5206, in pandas._libs.hashtable.PyObjectHashTable.get_item\nKeyError: 'price'\n\nThe above exception was the direct cause of the following exception:\n\nTraceback (most recent call last):\n  File \"/home/victordibia/projects/projectlida/lida/lib/lida/modules/executor.py\", line 139, in execute\n    exec(code, ex_locals)\n  File \"<string>\", line 13, in <module>\n  File \"<string>\", line 4, in plot\n  File \"/home/victordibia/.local/lib/python3.9/site-packages/pandas/core/frame.py\", line 3505, in __getitem__\n    indexer = self.columns.get_loc(key)\n  File \"/home/victordibia/.local/lib/python3.9/site-packages/pandas/core/indexes/base.py\", line 3623, in get_loc\n    raise KeyError(key) from err\nKeyError: 'price'\n"}}], [{"spec": null, "status": false, "raster": null, "code": "import matplotlib.pyplot as plt\nimport pandas as pd\n\ndef plot(data: pd.DataFrame):\n    data['date'] = pd.to_datetime(data['date'], format='%Y-%m-%d', errors='coerce')\n    plt.scatter(data['bedrooms'], data['price'], alpha=0.5)\n    plt.xlabel('Number of Bedrooms')\n    plt.ylabel('Price')\n    plt.title('What is the relationship between the number of bedrooms and the price of a property in the University District?')\n    return plt\n\nchart = plot(data)", "library": "matplotlib", "error": {"message": "'date'", "traceback": "Traceback (most recent call last):\n  File \"/home/victordibia/.local/lib/python3.9/site-packages/pandas/core/indexes/base.py\", line 3621, in get_loc\n    return self._engine.get_loc(casted_key)\n  File \"pandas/_libs/index.pyx\", line 136, in pandas._libs.index.IndexEngine.get_loc\n  File \"pandas/_libs/index.pyx\", line 163, in pandas._libs.index.IndexEngine.get_loc\n  File \"pandas/_libs/hashtable_class_helper.pxi\", line 5198, in pandas._libs.hashtable.PyObjectHashTable.get_item\n  File \"pandas/_libs/hashtable_class_helper.pxi\", line 5206, in pandas._libs.hashtable.PyObjectHashTable.get_item\nKeyError: 'date'\n\nThe above exception was the direct cause of the following exception:\n\nTraceback (most recent call last):\n  File \"/home/victordibia/projects/projectlida/lida/lib/lida/modules/executor.py\", line 139, in execute\n    exec(code, ex_locals)\n  File \"<string>\", line 12, in <module>\n  File \"<string>\", line 5, in plot\n  File \"/home/victordibia/.local/lib/python3.9/site-packages/pandas/core/frame.py\", line 3505, in __getitem__\n    indexer = self.columns.get_loc(key)\n  File \"/home/victordibia/.local/lib/python3.9/site-packages/pandas/core/indexes/base.py\", line 3623, in get_loc\n    raise KeyError(key) from err\nKeyError: 'date'\n"}}], [{"spec": null, "status": false, "raster": null, "code": "import matplotlib.pyplot as plt\nimport pandas as pd\ndef plot(data: pd.DataFrame):\n    data['property_type'].value_counts().plot(kind='bar')\n    plt.title('What is the most common type of property in the University District?', wrap=True)\n    return plt;\n\nchart = plot(data)", "library": "matplotlib", "error": {"message": "'property_type'", "traceback": "Traceback (most recent call last):\n  File \"/home/victordibia/.local/lib/python3.9/site-packages/pandas/core/indexes/base.py\", line 3621, in get_loc\n    return self._engine.get_loc(casted_key)\n  File \"pandas/_libs/index.pyx\", line 136, in pandas._libs.index.IndexEngine.get_loc\n  File \"pandas/_libs/index.pyx\", line 163, in pandas._libs.index.IndexEngine.get_loc\n  File \"pandas/_libs/hashtable_class_helper.pxi\", line 5198, in pandas._libs.hashtable.PyObjectHashTable.get_item\n  File \"pandas/_libs/hashtable_class_helper.pxi\", line 5206, in pandas._libs.hashtable.PyObjectHashTable.get_item\nKeyError: 'property_type'\n\nThe above exception was the direct cause of the following exception:\n\nTraceback (most recent call last):\n  File \"/home/victordibia/projects/projectlida/lida/lib/lida/modules/executor.py\", line 139, in execute\n    exec(code, ex_locals)\n  File \"<string>\", line 8, in <module>\n  File \"<string>\", line 4, in plot\n  File \"/home/victordibia/.local/lib/python3.9/site-packages/pandas/core/frame.py\", line 3505, in __getitem__\n    indexer = self.columns.get_loc(key)\n  File \"/home/victordibia/.local/lib/python3.9/site-packages/pandas/core/indexes/base.py\", line 3623, in get_loc\n    raise KeyError(key) from err\nKeyError: 'property_type'\n"}}], [{"spec": null, "status": false, "raster": null, "code": "import matplotlib.pyplot as plt\nimport pandas as pd\ndef plot(data: pd.DataFrame):\n    data['review_scores_rating'] = pd.to_numeric(data['review_scores_rating'], errors='coerce')\n    fig, ax = plt.subplots(figsize=(8,6))\n    ax.boxplot(data['review_scores_rating'].dropna(), vert=False, showmeans=True, meanline=True, labels=['Review Scores'])\n    ax.set_title('What is the average rating of properties in the University District?')\n    ax.axvline(data['review_scores_rating'].mean(), color='r', linestyle='--', label=f'Mean: {data[\"review_scores_rating\"].mean():.2f}')\n    ax.legend()\n    return plt;\n\nchart = plot(data)", "library": "matplotlib", "error": {"message": "'review_scores_rating'", "traceback": "Traceback (most recent call last):\n  File \"/home/victordibia/.local/lib/python3.9/site-packages/pandas/core/indexes/base.py\", line 3621, in get_loc\n    return self._engine.get_loc(casted_key)\n  File \"pandas/_libs/index.pyx\", line 136, in pandas._libs.index.IndexEngine.get_loc\n  File \"pandas/_libs/index.pyx\", line 163, in pandas._libs.index.IndexEngine.get_loc\n  File \"pandas/_libs/hashtable_class_helper.pxi\", line 5198, in pandas._libs.hashtable.PyObjectHashTable.get_item\n  File \"pandas/_libs/hashtable_class_helper.pxi\", line 5206, in pandas._libs.hashtable.PyObjectHashTable.get_item\nKeyError: 'review_scores_rating'\n\nThe above exception was the direct cause of the following exception:\n\nTraceback (most recent call last):\n  File \"/home/victordibia/projects/projectlida/lida/lib/lida/modules/executor.py\", line 139, in execute\n    exec(code, ex_locals)\n  File \"<string>\", line 12, in <module>\n  File \"<string>\", line 4, in plot\n  File \"/home/victordibia/.local/lib/python3.9/site-packages/pandas/core/frame.py\", line 3505, in __getitem__\n    indexer = self.columns.get_loc(key)\n  File \"/home/victordibia/.local/lib/python3.9/site-packages/pandas/core/indexes/base.py\", line 3623, in get_loc\n    raise KeyError(key) from err\nKeyError: 'review_scores_rating'\n"}}], [{"spec": null, "status": false, "raster": null, "code": "import matplotlib.pyplot as plt\nimport pandas as pd\ndef plot(data: pd.DataFrame):\n    data['distance'] = pd.to_numeric(data['distance'], errors='coerce')\n    data = data.dropna(subset=['distance'])\n    fig, ax = plt.subplots(figsize=(10, 6))\n    ax.hist(data['distance'], bins=20, color='blue', alpha=0.5)\n    ax.axvline(data['distance'].median(), color='red', linestyle='dashed', linewidth=2, label=f'Median: {data[\"distance\"].median():.2f}')\n    ax.set_xlabel('Distance from University of Washington')\n    ax.set_ylabel('Frequency')\n    ax.legend()\n    plt.title('What is the distribution of the distance between properties and the University of Washington?', wrap=True)\n    return plt;\n\nchart = plot(data)", "library": "matplotlib", "error": {"message": "'distance'", "traceback": "Traceback (most recent call last):\n  File \"/home/victordibia/.local/lib/python3.9/site-packages/pandas/core/indexes/base.py\", line 3621, in get_loc\n    return self._engine.get_loc(casted_key)\n  File \"pandas/_libs/index.pyx\", line 136, in pandas._libs.index.IndexEngine.get_loc\n  File \"pandas/_libs/index.pyx\", line 163, in pandas._libs.index.IndexEngine.get_loc\n  File \"pandas/_libs/hashtable_class_helper.pxi\", line 5198, in pandas._libs.hashtable.PyObjectHashTable.get_item\n  File \"pandas/_libs/hashtable_class_helper.pxi\", line 5206, in pandas._libs.hashtable.PyObjectHashTable.get_item\nKeyError: 'distance'\n\nThe above exception was the direct cause of the following exception:\n\nTraceback (most recent call last):\n  File \"/home/victordibia/projects/projectlida/lida/lib/lida/modules/executor.py\", line 139, in execute\n    exec(code, ex_locals)\n  File \"<string>\", line 15, in <module>\n  File \"<string>\", line 4, in plot\n  File \"/home/victordibia/.local/lib/python3.9/site-packages/pandas/core/frame.py\", line 3505, in __getitem__\n    indexer = self.columns.get_loc(key)\n  File \"/home/victordibia/.local/lib/python3.9/site-packages/pandas/core/indexes/base.py\", line 3623, in get_loc\n    raise KeyError(key) from err\nKeyError: 'distance'\n"}}]]}